Workbook

Sheet Tong quan
B2: THIẾT KẾ DATABASE MỚI — APP CHẤM ĐIỂM / KIỂM TRA POP & VMD
B5: Module | C5: Số bảng | D5: Bảng chính (Master) | E5: Mục đích nghiệp vụ | F5: Vấn đề chính của app cũ đã fix trong thiết kế mới
B6: Hệ thống / Dùng chung | C6: 9 | D6: NGUOI_DUNG | E6: Xác thực, phân quyền, danh mục quầy hàng/vai trò, menu, config module | F6: Gộp 37 roles + 5 cột phân quyền rời rạc (WORK) thành bảng join chuẩn hóa; tách Email/Role vào THONG_TIN_QUAY_HANG để xoá 30+ If-case hardcode
B7: Trang chủ | C7: 1 | D7: DANH_MUC_MENU_TRANG_CHU | E7: Cấu hình menu điều hướng trang chủ | F7: Giữ nguyên pattern config-table (đã tốt ở bản cũ)
B8: Công việc hàng ngày | C8: 2 | D8: DANH_MUC_CONG_VIEC | E8: Danh sách module công việc + phân quyền hiển thị theo ngành hàng | F8: Chuẩn hoá 5 cột 'Phân quyền 1-5' (có lỗi chính tả) thành 1 bảng join CONG_VIEC_PHAN_QUYEN nhiều dòng
B9: POP | C9: 4 | D9: CHAM_DIEM_POP | E9: Chấm điểm & theo dõi lỗi trưng bày POP/POS theo quầy hàng | F9: Bỏ 35 If-case Role→Quầy hàng (dùng THONG_TIN_QUAY_HANG.VaiTroMacDinh); thêm cột Điểm vào danh mục lỗi; RemoveIf thay Remove+LookUp để cascade delete đúng
B10: VMD | C10: 6 | D10: KIEM_TRA_VMD, CHAM_DIEM_VMD | E10: Kiểm tra & chấm điểm trưng bày Visual Merchandising theo 6 khu vực (VP/Bàn/Cột/Gondola/Sào/Vách) | F10: Gộp 6 bảng khu vực trùng cấu trúc (Kiểm tra VP/Bàn/Cột/Gondola/Sào/Vách và 6 bảng lỗi tương ứng) thành 2 bảng chi tiết dùng cột Khu vực; gộp 'Thông tin quầy kids' vào THONG_TIN_QUAY_HANG_VMD
B11: Mượn - Trả vật tư | C11: 3 | D11: PHIEU_MUON_TRA | E11: Quản lý phiếu mượn/trả vật tư trưng bày, ký nhận điện tử | F11: Thống nhất Tên đơn hàng dùng Lookup ở cả 2 form (thêm mới & chỉnh sửa) thay vì TextInput/Dropdown khác nhau
B12: Quản lý trang trí | C12: 1 | D12: PHIEU_TRANG_TRI | E12: Quản lý phiếu bàn giao công tác trang trí (bản sao nghiệp vụ của Mượn-Trả) | F12: Tách bảng riêng nhưng field/kiểu dữ liệu đồng bộ với PHIEU_MUON_TRA; xoá lệ thuộc DataSourceInfo() trỏ sai vào 'Ký nhận bàn giao'
B13: Báo cáo | C13: 2 | D13: DANH_MUC_BAO_CAO | E13: Cấu hình module báo cáo POP/VMD + phân quyền xem báo cáo | F13: Chuẩn hoá cột phân quyền như module Công việc hàng ngày
B16: Ghi chú:
B17: - Tổng cộng 23 bảng (SharePoint List) trong thiết kế mới, giảm từ ~34 bảng vật lý ở app cũ (do gộp 12 bảng khu vực VMD trùng cấu trúc).
B18: - Chi tiết field: xem sheet 'Chi tiet Field'. Danh sách bảng: xem sheet 'Danh sach Bang'. Quan hệ khóa ngoại: xem sheet 'Quan he'.
B19: - Các điểm cần khách hàng xác nhận trước khi triển khai: xem sheet 'Van de can lam ro'.

Sheet Danh sach Bang
A1: STT | B1: Tên bảng (mới) | C1: Tên bảng / List gốc (SharePoint cũ) | D1: Module | E1: Loại bảng | F1: Mô tả bảng | G1: Số field
A2: 1 | B2: NGUOI_DUNG | C2: USER | D2: Hệ thống / Dùng chung | E2: Master | F2: Tài khoản người dùng, thông tin đăng nhập và phân quyền. | G2: =COUNTIF('Chi tiet Field'!$B$2:$B$1000,B2) -> 10
A3: 2 | B3: DANH_MUC_VAI_TRO | C3: (mới - suy ra từ 37 roles hardcode) | D3: Hệ thống / Dùng chung | E3: Danh mục | F3: Danh mục 37 vai trò công việc (GL Ladies, Staff SPA...) và nhóm quyền tương ứng. | G3: =COUNTIF('Chi tiet Field'!$B$2:$B$1000,B3) -> 4
A4: 3 | B4: THONG_TIN_QUAY_HANG | C4: THÔNG TIN QUẦY HÀNG | D4: Hệ thống / Dùng chung | E4: Danh mục | F4: Danh mục Ngành hàng → Quầy hàng dùng chung cho POP, Mượn-Trả, Quản lý trang trí; mở rộng thêm Email & Vai trò mặc định. | G4: =COUNTIF('Chi tiet Field'!$B$2:$B$1000,B4) -> 6
A5: 4 | B5: THONG_TIN_QUAY_HANG_VMD | C5: THÔNG TIN QUẦY HÀNG VMD + Thông tin quầy kids | D5: Hệ thống / Dùng chung | E5: Danh mục | F5: Danh mục Ngành hàng → Quầy hàng riêng cho VMD (chỉ Softline/Hardline + Kids), gộp bảng Kids riêng biệt của app cũ. | G5: =COUNTIF('Chi tiet Field'!$B$2:$B$1000,B5) -> 6
A6: 5 | B6: DANH_MUC_MENU_TRANG_CHU | C6: HOME | D6: Trang chủ | E6: Danh mục | F6: Cấu hình các mục menu hiển thị trên màn hình Trang chủ. | G6: =COUNTIF('Chi tiet Field'!$B$2:$B$1000,B6) -> 5
A7: 6 | B7: DANH_MUC_CONG_VIEC | C7: WORK | D7: Công việc hàng ngày | E7: Danh mục | F7: Danh mục các module công việc hàng ngày (Chấm điểm POP, Kiểm tra VMD, Mượn-Trả...). | G7: =COUNTIF('Chi tiet Field'!$B$2:$B$1000,B7) -> 5
A8: 7 | B8: CONG_VIEC_PHAN_QUYEN | C8: WORK.'Phân quyền 1-5' (5 cột) | D8: Công việc hàng ngày | E8: Bảng liên kết (join) | F8: Phân quyền hiển thị module công việc theo nhóm ngành hàng — thay thế 5 cột rời rạc bằng nhiều dòng dữ liệu. | G8: =COUNTIF('Chi tiet Field'!$B$2:$B$1000,B8) -> 3
A9: 8 | B9: DANH_MUC_BAO_CAO | C9: Báo cáo POPVMD | D9: Báo cáo | E9: Danh mục | F9: Danh mục các module báo cáo (Báo cáo kiểm tra POP, chấm điểm POP, kiểm tra VMD...). | G9: =COUNTIF('Chi tiet Field'!$B$2:$B$1000,B9) -> 4
A10: 9 | B10: BAO_CAO_PHAN_QUYEN | C10: Báo cáo POPVMD.'Phân quyền 1-5' | D10: Báo cáo | E10: Bảng liên kết (join) | F10: Phân quyền xem từng module báo cáo theo nhóm ngành hàng. | G10: =COUNTIF('Chi tiet Field'!$B$2:$B$1000,B10) -> 3
A11: 10 | B11: CHAM_DIEM_POP | C11: CHẤM ĐIỂM POP | D11: POP | E11: Master | F11: Phiên chấm điểm trưng bày POP/POS tại một quầy hàng, tại một thời điểm. | G11: =COUNTIF('Chi tiet Field'!$B$2:$B$1000,B11) -> 8
A12: 11 | B12: LOI_TRUNG_BAY_POP | C12: LỖI TRƯNG BÀY POP | D12: POP | E12: Chi tiết (child) | F12: Từng lỗi trưng bày cụ thể ghi nhận trong một phiên chấm điểm POP (1 phiên có N lỗi). | G12: =COUNTIF('Chi tiet Field'!$B$2:$B$1000,B12) -> 12
A13: 12 | B13: DANH_MUC_LOI_POP | C13: Thông tin lỗi POP | D13: POP | E13: Danh mục | F13: Danh mục loại lỗi vi phạm trưng bày POP kèm điểm phạt chuẩn. | G13: =COUNTIF('Chi tiet Field'!$B$2:$B$1000,B13) -> 3
... A24: 23 | B24: PHIEU_TRANG_TRI | C24: Quản lý trang trí_1 | D24: Quản lý trang trí | E24: Master | F24: Phiếu bàn giao công tác trang trí quầy hàng (cấu trúc tương tự Mượn-Trả). | G24: =COUNTIF('Chi tiet Field'!$B$2:$B$1000,B24) -> 14

Sheet Chi tiet Field
A1: STT | B1: Tên bảng | C1: Tên field | D1: Khóa | E1: Kiểu dữ liệu (SharePoint) | F1: Bắt buộc | G1: Mô tả field | H1: Ghi chú / Đề xuất fix
A2: 1 | B2: NGUOI_DUNG | C2: ID | D2: PK | E2: Số (Number) | F2: Có | G2: Khóa chính, SharePoint ID tự sinh.
A3: 2 | B3: NGUOI_DUNG | C3: Username | E3: Văn bản một dòng | F3: Có | G3: Tên đăng nhập dùng để xác thực (unique).
A4: 3 | B4: NGUOI_DUNG | C4: Password | E4: Văn bản một dòng | F4: Có | G4: Mật khẩu. | H4: Bảo mật yếu (plain text) ở app cũ — đề xuất chuyển sang Azure AD/Entra ID khi rebuild.
A5: 4 | B5: NGUOI_DUNG | C5: HoTen | E5: Văn bản một dòng | F5: Có | G5: Họ tên hiển thị (Fullname).
A6: 5 | B6: NGUOI_DUNG | C6: VaiTro | D6: FK → DANH_MUC_VAI_TRO | E6: Tra cứu (Lookup) | F6: Có | G6: Vai trò công việc của user (VD: GL Ladies, Staff SPA...). | H6: - Lớp phân quyền data
A7: 6 | B7: NGUOI_DUNG | C7: PhanQuyen | E7: Lựa chọn (Choice): SPA / Ngành hàng / Test | F7: Có | G7: Nhóm quyền cấp cao dùng để bật/tắt chức năng (Disabled/Edit) trên các màn hình.
A8: 7 | B8: NGUOI_DUNG | C8: NhomNganhHang | E8: Lựa chọn (Choice): FOODLINE 1 / FOODLINE 2 / SOFTLINE / HARDLINE / SM / SPA | F8: Không | G8: Biến usernh cũ — nhóm ngành hàng cấp cao dùng filter module & báo cáo. | H8: - Xem menu nào
A9: 8 | B9: NGUOI_DUNG | C9: QuayHangMacDinh | D9: FK → THONG_TIN_QUAY_HANG | E9: Tra cứu (Lookup) | F9: Không | G9: Quầy hàng mặc định của user. | H9: Mới — thay thế 18-35 If-case hardcode Role→Quầy hàng trong code cũ.
A10: 9 | B10: NGUOI_DUNG | C10: HinhAnh | E10: Hình ảnh | F10: Không | G10: Ảnh đại diện người dùng.
A11: 10 | B11: NGUOI_DUNG | C11: TrangThai | E11: Có/Không (Yes/No) | F11: Có | G11: Tài khoản còn hoạt động hay không. | H11: Mới — phục vụ quản lý tài khoản, app cũ không có.
A12: 11 | B12: DANH_MUC_VAI_TRO | C12: ID | D12: PK | E12: Số (Number) | F12: Có | G12: Khóa chính.
A13: 12 | B13: DANH_MUC_VAI_TRO | C13: TenVaiTro | E13: Văn bản một dòng | F13: Có | G13: Tên vai trò (VD: GL Ladies, Staff SPA, GL SPA...) — 37 giá trị ở app cũ, unique.
A14: 13 | B14: DANH_MUC_VAI_TRO | C14: NhomVaiTro | E14: Lựa chọn (Choice): SPA / Food / Softline / Hardline / Group / Dev | F14: Có | G14: Nhóm lớn của vai trò dùng để phân loại quyền truy cập theo module (VMD chỉ áp dụng Softline/Hardline).
A15: 14 | B15: DANH_MUC_VAI_TRO | C15: PhanQuyenMacDinh | E15: Lựa chọn (Choice): SPA / Ngành hàng / Test | F15: Không | G15: Permission mặc định gán cho vai trò này khi tạo user mới.
A16: 15 | B16: THONG_TIN_QUAY_HANG | C16: ID | D16: PK | E16: Số (Number) | F16: Có | G16: Khóa chính.
A17: 16 | B17: THONG_TIN_QUAY_HANG | C17: NganhHang | E17: Văn bản một dòng / Lựa chọn | F17: Có | G17: Tên ngành hàng (VD: Ladies, Fish, Household 2F...).
A18: 17 | B18: THONG_TIN_QUAY_HANG | C18: QuayHang | E18: Văn bản một dòng | F18: Có | G18: Tên quầy hàng cụ thể (unique) — dùng cho cascading dropdown Ngành hàng→Quầy hàng.
A19: 18 | B19: THONG_TIN_QUAY_HANG | C19: VaiTroMacDinh | D19: FK → DANH_MUC_VAI_TRO | E19: Tra cứu (Lookup) | F19: Không | G19: Vai trò tương ứng quầy hàng này. | H19: Mới — thay thế 35 If-case mapping Role→Quầy hàng trong màn 'Chấm điểm POP'.
A20: 19 | B20: THONG_TIN_QUAY_HANG | C20: Email | E20: Văn bản một dòng | F20: Không | G20: Email nhận thông báo khi có lỗi trưng bày mới. | H20: Mới — thay thế 30 If-case hardcode email trong 'Gửi thông báo'. Cần xác nhận case Sport=Inner, Stationery=Multimedia có đúng nghiệp vụ hay là bug (xem Van de can lam ro).
A21: 20 | B21: THONG_TIN_QUAY_HANG | C21: GhiChu | E21: Văn bản nhiều dòng | F21: Không | G21: Ghi chú thêm.
A22: 21 | B22: THONG_TIN_QUAY_HANG_VMD | C22: ID | D22: PK | E22: Số (Number) | F22: Có | G22: Khóa chính.
A23: 22 | B23: THONG_TIN_QUAY_HANG_VMD | C23: NganhHang | E23: Văn bản một dòng | F23: Có | G23: Tên ngành hàng (chỉ Softline/Hardline).
A24: 23 | B24: THONG_TIN_QUAY_HANG_VMD | C24: QuayHang | E24: Văn bản một dòng | F24: Có | G24: Tên quầy hàng cụ thể (unique).
A25: 24 | B25: THONG_TIN_QUAY_HANG_VMD | C25: VaiTroMacDinh | D25: FK → DANH_MUC_VAI_TRO | E25: Tra cứu (Lookup) | F25: Không | G25: Vai trò tương ứng quầy hàng này. | H25: Thay thế 18 If-case hardcode Role→Quầy hàng trong màn VMD.
A26: 25 | B26: THONG_TIN_QUAY_HANG_VMD | C26: Email | E26: Văn bản một dòng | F26: Không | G26: Email nhận thông báo lỗi VMD. | H26: Mới — thay 17 If-case hardcode email.
A27: 26 | F27: Có | G27: Phân biệt quầy hàng thường và quầy Kids. | H27: Gộp bảng 'Thông tin quầy kids' riêng biệt (dành cho user '1004.dlkids') vào bảng này để tránh duplicate cấu trúc.
A28: 27 | B28: THONG_TIN_QUAY_HANG_VMD | C28: GhiChu | E28: Văn bản nhiều dòng | F28: Không | G28: Ghi chú thêm.
A29: 28 | B29: DANH_MUC_MENU_TRANG_CHU | C29: ID | D29: PK | E29: Số (Number) | F29: Có | G29: Khóa chính.
A30: 29 | B30: DANH_MUC_MENU_TRANG_CHU | C30: TenMenu | E30: Văn bản một dòng | F30: Có | G30: Tên mục menu hiển thị ở Trang chủ (Name Group).
A31: 30 | B31: DANH_MUC_MENU_TRANG_CHU | C31: HinhAnh | E31: Hình ảnh | F31: Không | G31: Icon hiển thị trong gallery.
A32: 31 | B32: DANH_MUC_MENU_TRANG_CHU | C32: ManHinhDich | E32: Văn bản một dòng | F32: Có | G32: Tên màn hình điều hướng đến khi chọn menu này. | H32: Mới — làm rõ mục tiêu Navigate, tránh phải sửa code khi đổi luồng.
A33: 32 | B33: DANH_MUC_MENU_TRANG_CHU | C33: ThuTu | E33: Số (Number) | F33: Không | G33: Thứ tự hiển thị trong gallery.
A34: 33 | B34: DANH_MUC_CONG_VIEC | C34: ID | D34: PK | E34: Số (Number) | F34: Có | G34: Khóa chính.
A35: 34 | B35: DANH_MUC_CONG_VIEC | C35: TenModule | E35: Văn bản một dòng | F35: Có | G35: Tên module công việc (VD: Chấm điểm POP, Kiểm tra VMD, Mượn-Trả vật tư...).
A36: 35 | B36: DANH_MUC_CONG_VIEC | C36: HinhAnh | E36: Hình ảnh | F36: Không | G36: Icon hiển thị.
A37: 36 | B37: DANH_MUC_CONG_VIEC | C37: ManHinhDich | E37: Văn bản một dòng | F37: Có | G37: Tên màn hình điều hướng đến.
A38: 37 | B38: DANH_MUC_CONG_VIEC | C38: ThuTu | E38: Số (Number) | F38: Không | G38: Thứ tự hiển thị.
A39: 38 | B39: CONG_VIEC_PHAN_QUYEN | C39: ID | D39: PK | E39: Số (Number) | F39: Có | G39: Khóa chính.
A40: 39 | B40: CONG_VIEC_PHAN_QUYEN | C40: ModuleID | D40: FK → DANH_MUC_CONG_VIEC | E40: Tra cứu (Lookup) | F40: Có | G40: Module công việc được cấp quyền xem.
...

Sheet Quan he
A1: Bảng (N / con) | B1: Field khóa ngoại | C1: Bảng tham chiếu (1 / cha) | D1: Loại quan hệ | E1: Ghi chú
A2: NGUOI_DUNG | B2: VaiTro | C2: DANH_MUC_VAI_TRO | D2: N-1
A3: NGUOI_DUNG | B3: QuayHangMacDinh | C3: THONG_TIN_QUAY_HANG | D3: N-1 | E3: Tùy chọn
A4: THONG_TIN_QUAY_HANG | B4: VaiTroMacDinh | C4: DANH_MUC_VAI_TRO | D4: N-1
A5: THONG_TIN_QUAY_HANG_VMD | B5: VaiTroMacDinh | C5: DANH_MUC_VAI_TRO | D5: N-1
A6: CONG_VIEC_PHAN_QUYEN | B6: ModuleID | C6: DANH_MUC_CONG_VIEC | D6: N-1 | E6: Chuẩn hóa 5 cột Phân quyền 1-5 cũ
A7: BAO_CAO_PHAN_QUYEN | B7: BaoCaoID | C7: DANH_MUC_BAO_CAO | D7: N-1 | E7: Chuẩn hóa 5 cột Phân quyền 1-5 cũ
A8: CHAM_DIEM_POP | B8: QuayHang | C8: THONG_TIN_QUAY_HANG | D8: N-1
A9: CHAM_DIEM_POP | B9: NguoiDungID | C9: NGUOI_DUNG | D9: N-1
A10: LOI_TRUNG_BAY_POP | B10: RefID | C10: CHAM_DIEM_POP | D10: N-1 (1 phiên - N lỗi) | E10: Cascade delete: xóa CHAM_DIEM_POP phải RemoveIf toàn bộ LOI_TRUNG_BAY_POP liên quan (bug ở app cũ chỉ xóa 1 dòng)
A11: LOI_TRUNG_BAY_POP | B11: LoiViPham | C11: DANH_MUC_LOI_POP | D11: N-1
A12: KIEM_TRA_VMD | B12: QuayHang | C12: THONG_TIN_QUAY_HANG_VMD | D12: N-1
A13: KIEM_TRA_VMD | B13: NguoiDungID | C13: NGUOI_DUNG | D13: N-1
A14: KIEM_TRA_VMD_CHI_TIET | B14: RefID | C14: KIEM_TRA_VMD | D14: N-1 (1 phiên - tối đa 6 khu vực) | E14: Cascade delete RemoveIf khi xóa phiên kiểm tra cha
A15: KIEM_TRA_VMD_CHI_TIET | B15: KetQua | C15: DANH_MUC_LOI_KIEM_TRA_VMD | D15: N-1 | E15: Lọc theo KhuVuc tương ứng
A16: CHAM_DIEM_VMD | B16: QuayHang | C16: THONG_TIN_QUAY_HANG_VMD | D16: N-1
A17: CHAM_DIEM_VMD | B17: NguoiDungID | C17: NGUOI_DUNG | D17: N-1
A18: CHAM_DIEM_VMD_CHI_TIET | B18: RefID | C18: CHAM_DIEM_VMD | D18: N-1 (1 phiên - tối đa 6 khu vực) | E18: Cascade delete RemoveIf khi xóa phiên chấm điểm cha
A19: CHAM_DIEM_VMD_CHI_TIET | B19: LoiTrungBay | C19: DANH_MUC_LOI_CHAM_DIEM_VMD | D19: N-1 | E19: Lọc theo KhuVuc + NhomQuayHang tương ứng
A20: PHIEU_MUON_TRA | B20: QuayHang | C20: THONG_TIN_QUAY_HANG | D20: N-1
A21: PHIEU_MUON_TRA | B21: TenDonHang | C21: DANH_MUC_TEN_DON_HANG | D21: N-1
A22: PHIEU_MUON_TRA | B22: NguoiDungID | C22: NGUOI_DUNG | D22: N-1
A23: PHIEU_TRANG_TRI | B23: QuayHang | C23: THONG_TIN_QUAY_HANG | D23: N-1
A24: PHIEU_TRANG_TRI | B24: NguoiDungID | C24: NGUOI_DUNG | D24: N-1

Sheet Van de can lam ro
A1: # | B1: Vấn đề / Câu hỏi cần khách hàng xác nhận | C1: Ảnh hưởng đến bảng nào
A2: 1 | B2: Bảng 'KIỂM TRA TRƯNG BÀY POP' dùng trong màn hình Báo cáo kiểm tra POP có phải cùng dữ liệu với LỖI TRƯNG BÀY POP, hay là một luồng nghiệp vụ 'Kiểm tra POP' hoàn toàn riêng (chưa có màn hình được phân tích/upload)? Cần bổ sung YAML/JSON các màn hình liên quan nếu có. | C2: KIEM_TRA_TRUNG_BAY_POP
A3: 2 | B3: Có giữ mật khẩu trong bảng người dùng (Password dạng văn bản) hay chuyển sang xác thực Azure AD / Microsoft Entra ID khi rebuild? Quyết định này ảnh hưởng lớn tới thiết kế bảng NGUOI_DUNG và cơ chế đăng nhập. | C3: NGUOI_DUNG
A4: 3 | B4: Trường 'Tháng' (dạng text 'Tháng 01'...'Tháng 12') xuất hiện lặp lại ở nhiều bảng dữ liệu — có cần giữ lại để tương thích báo cáo cũ, hay bỏ hẳn và tính trực tiếp từ Created bằng công thức/view? | C4: CHAM_DIEM_POP, LOI_TRUNG_BAY_POP, KIEM_TRA_VMD, KIEM_TRA_VMD_CHI_TIET, CHAM_DIEM_VMD, CHAM_DIEM_VMD_CHI_TIET
A5: 4 | B5: Email thông báo: Sport dùng chung email với Inner, Stationery dùng chung email với Multimedia ở app cũ — đây là chủ ý nghiệp vụ hay là lỗi cấu hình cần sửa khi thiết lập THONG_TIN_QUAY_HANG.Email? | C5: THONG_TIN_QUAY_HANG, THONG_TIN_QUAY_HANG_VMD
A6: 5 | B6: Cơ chế xóa liên quan (cascade delete) giữa bảng cha/con: nên tiếp tục dùng RemoveIf trong Power Apps, hay chuyển sang Power Automate Flow / trigger ở tầng Dataverse để đảm bảo toàn vẹn dữ liệu khi khối lượng lớn? | C6: LOI_TRUNG_BAY_POP, KIEM_TRA_VMD_CHI_TIET, CHAM_DIEM_VMD_CHI_TIET
A7: 6 | B7: Danh mục trạng thái 'Đang mượn / Đã trả / Hư hỏng / Thiếu' của Mượn-Trả vật tư có áp dụng đúng cho Quản lý trang trí, hay module này cần một danh mục trạng thái riêng phù hợp nghiệp vụ thi công/trang trí hơn? | C7: PHIEU_TRANG_TRI, DANH_MUC_TRANG_THAI_MUON_TRA
A8: 7 | B8: Danh sách đầy đủ 37 vai trò (Role) và mapping Role → Quầy hàng → Email hiện chỉ thấy một phần trong tài liệu gốc (một số bảng bị lược bớt '•••'). Đề nghị khách hàng cung cấp danh sách đầy đủ để nhập liệu chính xác cho DANH_MUC_VAI_TRO và THONG_TIN_QUAY_HANG. | C8: DANH_MUC_VAI_TRO, THONG_TIN_QUAY_HANG, THONG_TIN_QUAY_HANG_VMD
A9: 8 | B9: Khối lượng dữ liệu dự kiến (số phiên chấm điểm/kiểm tra mỗi tháng, số năm lưu trữ) — nếu vượt ngưỡng ~5.000-2.000.000 dòng/list hoặc cần filter phức tạp không delegable, nên cân nhắc Dataverse thay vì SharePoint Online để tránh giới hạn hiệu năng. | C9: Toàn bộ các bảng giao dịch (CHAM_DIEM_POP, LOI_TRUNG_BAY_POP, KIEM_TRA_VMD*, CHAM_DIEM_VMD*, PHIEU_MUON_TRA, PHIEU_TRANG_TRI)
A10: 9 | B10: Trường 'Điểm của [Khu vực]' hiển thị dấu trừ ở app cũ chỉ là format hiển thị (không phải giá trị lưu thực). Khi rebuild, có cần lưu giá trị âm thực sự trong Diem hay vẫn lưu dương và xử lý hiển thị ở tầng UI? | C10: CHAM_DIEM_VMD_CHI_TIET, LOI_TRUNG_BAY_POP
